Workbook
Name Datenliste: #REF!
Name eurrate: '[1]CAPEX Comparison Sheet'!#REF!
Name eurrate: '[1]CAPEX Comparison Sheet'!#REF!
Name eurrate: '[1]CAPEX Comparison Sheet'!#REF!
Name eurrate: '[1]CAPEX Comparison Sheet'!#REF!
Name eurrate: '[1]CAPEX Comparison Sheet'!#REF!
Name eurrate: '[1]CAPEX Comparison Sheet'!#REF!
Name eurrate: '[1]CAPEX Comparison Sheet'!#REF!
Name eurrate: '[1]CAPEX Comparison Sheet'!#REF!
Name eurrate: '[1]CAPEX Comparison Sheet'!#REF!
Name eurrate: '[1]CAPEX Comparison Sheet'!#REF!
Name eurrate: #REF!
Name usdrate: '[1]CAPEX Comparison Sheet'!#REF!
Name usdrate: '[1]CAPEX Comparison Sheet'!#REF!
Name usdrate: '[1]CAPEX Comparison Sheet'!#REF!
Name usdrate: '[1]CAPEX Comparison Sheet'!#REF!
Name usdrate: '[1]CAPEX Comparison Sheet'!#REF!
Name usdrate: '[1]CAPEX Comparison Sheet'!#REF!
Name usdrate: '[1]CAPEX Comparison Sheet'!#REF!
Name usdrate: '[1]CAPEX Comparison Sheet'!#REF!
Name usdrate: '[1]CAPEX Comparison Sheet'!#REF!
Name usdrate: '[1]CAPEX Comparison Sheet'!#REF!
Name usdrate: #REF!

Sheet calc
D1: loc curr | G1: comp curr | H1: comp curr | I1: comp curr | J1: comp curr | K1: comp curr | L1: comp curr | M1: comp curr | Q1: comp curr | S1: loc curr | T1: loc curr | U1: loc curr | V1: comp curr | W1: comp curr | X1: comp curr | Y1: comp curr
A2: 0 | B2: Supplier | C2: currency | D2: last avail. Cost | E2: class | F2: selected curr | G2: final landed | H2: initial | I2: revised | J2: final | K2: sav ini/fin | L2: sav ini/rev | M2: sav rev/fin | N2: sav ini/fin | O2: sav ini/rev | P2: sav rev/fin | Q2: sav RAS | R2: sav RAS | S2: cost ini | T2: cost rev | U2: cost fin | V2: ini landed | W2: rev landed | X2: last avail. Land | Y2: last avail. Cost
A3: 2 | B3: ='1. MPBC'!G10 -> Supplier 1 | C3: ='1. MPBC'!G28 -> 0 | D3: =IFERROR(IF(U3="",IF(T3="",S3,T3),U3),"") | E3: ='1. MPBC'!I20 -> <-- select country | F3: ='1. MPBC'!$D$28 -> 0 | G3: ='1. MPBC'!I40 | H3: ='1. MPBC'!G39 | I3: ='1. MPBC'!H39 | J3: ='1. MPBC'!I39 | K3: =IF(J3=0,"",IFERROR(H3-J3,"")) | L3: =IF(I3=0,"",IFERROR(H3-I3,"")) | M3: =IF(J3=0,"",IFERROR(I3-J3,"")) | N3: =IFERROR(K3/H3,"") | O3: =IFERROR(L3/H3,"") | P3: =IFERROR(M3/I3,"") | Q3: =IFERROR($C$14-J3,"") | R3: =IFERROR(Q3/$C$14,"") | S3: ='1. MPBC'!G38 | T3: ='1. MPBC'!H38 | U3: ='1. MPBC'!I38 | V3: ='1. MPBC'!G40 | W3: ='1. MPBC'!H40 | X3: =IFERROR(IF(G3="",IF(W3="",V3,W3),G3),"") | Y3: =IFERROR(IF(J3="",IF(I3="",H3,I3),J3),"")
A4: 0 | B4: ='1. MPBC'!K10 -> Supplier 2 | C4: ='1. MPBC'!K28 -> 0 | D4: =IFERROR(IF(U4="",IF(T4="",S4,T4),U4),"") | E4: ='1. MPBC'!M20 -> <-- select country | F4: ='1. MPBC'!$D$28 -> 0 | G4: ='1. MPBC'!M40 | H4: ='1. MPBC'!K39 | I4: ='1. MPBC'!L39 | J4: ='1. MPBC'!M39 | K4: =IF(J4=0,"",IFERROR(H4-J4,"")) | L4: =IF(I4=0,"",IFERROR(H4-I4,"")) | M4: =IF(J4=0,"",IFERROR(I4-J4,"")) | N4: =IFERROR(K4/H4,"") | O4: =IFERROR(L4/H4,"") | P4: =IFERROR(M4/I4,"") | Q4: =IFERROR($C$14-J4,"") | R4: =IFERROR(Q4/$C$14,"") | S4: ='1. MPBC'!K38 | T4: ='1. MPBC'!L38 | U4: ='1. MPBC'!M38 | V4: ='1. MPBC'!K40 | W4: ='1. MPBC'!L40 | X4: =IFERROR(IF(G4="",IF(W4="",V4,W4),G4),"") | Y4: =IFERROR(IF(J4="",IF(I4="",H4,I4),J4),"")
A5: 9 | B5: ='1. MPBC'!O10 -> Supplier 3 | C5: ='1. MPBC'!O28 -> 0 | D5: =IFERROR(IF(U5="",IF(T5="",S5,T5),U5),"") | E5: ='1. MPBC'!Q20 -> <-- select country | F5: ='1. MPBC'!$D$28 -> 0 | G5: ='1. MPBC'!Q40 | H5: ='1. MPBC'!O39 | I5: ='1. MPBC'!P39 | J5: ='1. MPBC'!Q39 | K5: =IF(J5=0,"",IFERROR(H5-J5,"")) | L5: =IF(I5=0,"",IFERROR(H5-I5,"")) | M5: =IF(J5=0,"",IFERROR(I5-J5,"")) | N5: =IFERROR(K5/H5,"") | O5: =IFERROR(L5/H5,"") | P5: =IFERROR(M5/I5,"") | Q5: =IFERROR($C$14-J5,"") | R5: =IFERROR(Q5/$C$14,"") | S5: ='1. MPBC'!O38 | T5: ='1. MPBC'!P38 | U5: ='1. MPBC'!Q38 | V5: ='1. MPBC'!O40 | W5: ='1. MPBC'!P40 | X5: =IFERROR(IF(G5="",IF(W5="",V5,W5),G5),"") | Y5: =IFERROR(IF(J5="",IF(I5="",H5,I5),J5),"")
A6: 2 | B6: ='1. MPBC'!W10 -> Supplier 4 | C6: ='1. MPBC'!W28 -> 0 | D6: =IFERROR(IF(U6="",IF(T6="",S6,T6),U6),"") | E6: ='1. MPBC'!Y20 -> <-- select country | F6: ='1. MPBC'!$D$28 -> 0 | G6: ='1. MPBC'!Y40 | H6: ='1. MPBC'!W39 | I6: ='1. MPBC'!X39 | J6: ='1. MPBC'!Y39 | K6: =IF(J6=0,"",IFERROR(H6-J6,"")) | L6: =IF(I6=0,"",IFERROR(H6-I6,"")) | M6: =IF(J6=0,"",IFERROR(I6-J6,"")) | N6: =IFERROR(K6/H6,"") | O6: =IFERROR(L6/H6,"") | P6: =IFERROR(M6/I6,"") | Q6: =IFERROR($C$14-J6,"") | R6: =IFERROR(Q6/$C$14,"") | S6: ='1. MPBC'!W38 | T6: ='1. MPBC'!X38 | U6: ='1. MPBC'!Y38 | V6: ='1. MPBC'!W40 | W6: ='1. MPBC'!X40 | X6: =IFERROR(IF(G6="",IF(W6="",V6,W6),G6),"") | Y6: =IFERROR(IF(J6="",IF(I6="",H6,I6),J6),"")
A7: 0 | B7: ='1. MPBC'!AA10 -> Supplier 5 | C7: ='1. MPBC'!AA28 -> 0 | D7: =IFERROR(IF(U7="",IF(T7="",S7,T7),U7),"") | E7: ='1. MPBC'!AC20 -> <-- select country | F7: ='1. MPBC'!$D$28 -> 0 | G7: ='1. MPBC'!AC40 | H7: ='1. MPBC'!AA39 | I7: ='1. MPBC'!AB39 | J7: ='1. MPBC'!AC39 | K7: =IF(J7=0,"",IFERROR(H7-J7,"")) | L7: =IF(I7=0,"",IFERROR(H7-I7,"")) | M7: =IF(J7=0,"",IFERROR(I7-J7,"")) | N7: =IFERROR(K7/H7,"") | O7: =IFERROR(L7/H7,"") | P7: =IFERROR(M7/I7,"") | Q7: =IFERROR($C$14-J7,"") | R7: =IFERROR(Q7/$C$14,"") | S7: ='1. MPBC'!AA38 | T7: ='1. MPBC'!AB38 | U7: ='1. MPBC'!AC38 | V7: ='1. MPBC'!AA40 | W7: ='1. MPBC'!AB40 | X7: =IFERROR(IF(G7="",IF(W7="",V7,W7),G7),"") | Y7: =IFERROR(IF(J7="",IF(I7="",H7,I7),J7),"")
A8: 2 | B8: ='1. MPBC'!AE10 -> Supplier 6 | C8: ='1. MPBC'!AE28 -> 0 | D8: =IFERROR(IF(U8="",IF(T8="",S8,T8),U8),"") | E8: ='1. MPBC'!AG20 -> <-- select country | F8: ='1. MPBC'!$D$28 -> 0 | G8: ='1. MPBC'!AG40 | H8: ='1. MPBC'!AE39 | I8: ='1. MPBC'!AF39 | J8: ='1. MPBC'!AG39 | K8: =IF(J8=0,"",IFERROR(H8-J8,"")) | L8: =IF(I8=0,"",IFERROR(H8-I8,"")) | M8: =IF(J8=0,"",IFERROR(I8-J8,"")) | N8: =IFERROR(K8/H8,"") | O8: =IFERROR(L8/H8,"") | P8: =IFERROR(M8/I8,"") | Q8: =IFERROR($C$14-J8,"") | R8: =IFERROR(Q8/$C$14,"") | S8: ='1. MPBC'!AE38 | T8: ='1. MPBC'!AF38 | U8: ='1. MPBC'!AG38 | V8: ='1. MPBC'!AE40 | W8: ='1. MPBC'!AF40 | X8: =IFERROR(IF(G8="",IF(W8="",V8,W8),G8),"") | Y8: =IFERROR(IF(J8="",IF(I8="",H8,I8),J8),"")
A9: 5 | B9: ='1. MPBC'!AI10 -> Supplier 7 | C9: ='1. MPBC'!AI28 -> 0 | D9: =IFERROR(IF(U9="",IF(T9="",S9,T9),U9),"") | E9: ='1. MPBC'!AK20 -> <-- select country | F9: ='1. MPBC'!$D$28 -> 0 | G9: ='1. MPBC'!AK40 | H9: ='1. MPBC'!AI39 | I9: ='1. MPBC'!AJ39 | J9: ='1. MPBC'!AK39 | K9: =IF(J9=0,"",IFERROR(H9-J9,"")) | L9: =IF(I9=0,"",IFERROR(H9-I9,"")) | M9: =IF(J9=0,"",IFERROR(I9-J9,"")) | N9: =IFERROR(K9/H9,"") | O9: =IFERROR(L9/H9,"") | P9: =IFERROR(M9/I9,"") | Q9: =IFERROR($C$14-J9,"") | R9: =IFERROR(Q9/$C$14,"") | S9: ='1. MPBC'!AI38 | T9: ='1. MPBC'!AJ38 | U9: ='1. MPBC'!AK38 | V9: ='1. MPBC'!AI40 | W9: ='1. MPBC'!AJ40 | X9: =IFERROR(IF(G9="",IF(W9="",V9,W9),G9),"") | Y9: =IFERROR(IF(J9="",IF(I9="",H9,I9),J9),"")
A10: - | B10: ='1. MPBC'!AM10 -> Supplier 8 | C10: ='1. MPBC'!AM28 -> 0 | D10: =IFERROR(IF(U10="",IF(T10="",S10,T10),U10),"") | E10: ='1. MPBC'!AO20 -> <-- select country | F10: ='1. MPBC'!$D$28 -> 0 | G10: ='1. MPBC'!AO40 | H10: ='1. MPBC'!AM39 | I10: ='1. MPBC'!AN39 | J10: ='1. MPBC'!AO39 | K10: =IF(J10=0,"",IFERROR(H10-J10,"")) | L10: =IF(I10=0,"",IFERROR(H10-I10,"")) | M10: =IF(J10=0,"",IFERROR(I10-J10,"")) | N10: =IFERROR(K10/H10,"") | O10: =IFERROR(L10/H10,"") | P10: =IFERROR(M10/I10,"") | Q10: =IFERROR($C$14-J10,"") | R10: =IFERROR(Q10/$C$14,"") | S10: ='1. MPBC'!AM38 | T10: ='1. MPBC'!AN38 | U10: ='1. MPBC'!AO38 | V10: ='1. MPBC'!AM40 | W10: ='1. MPBC'!AN40 | X10: =IFERROR(IF(G10="",IF(W10="",V10,W10),G10),"") | Y10: =IFERROR(IF(J10="",IF(I10="",H10,I10),J10),"")
A11: v | B11: ='1. MPBC'!AQ10 -> Supplier 9 | C11: ='1. MPBC'!AQ28 -> 0 | D11: =IFERROR(IF(U11="",IF(T11="",S11,T11),U11),"") | E11: ='1. MPBC'!AS20 -> <-- select country | F11: ='1. MPBC'!$D$28 -> 0 | G11: ='1. MPBC'!AS40 | H11: ='1. MPBC'!AQ39 | I11: ='1. MPBC'!AR39 | J11: ='1. MPBC'!AS39 | K11: =IF(J11=0,"",IFERROR(H11-J11,"")) | L11: =IF(I11=0,"",IFERROR(H11-I11,"")) | M11: =IF(J11=0,"",IFERROR(I11-J11,"")) | N11: =IFERROR(K11/H11,"") | O11: =IFERROR(L11/H11,"") | P11: =IFERROR(M11/I11,"") | Q11: =IFERROR($C$14-J11,"") | R11: =IFERROR(Q11/$C$14,"") | S11: ='1. MPBC'!AQ38 | T11: ='1. MPBC'!AR38 | U11: ='1. MPBC'!AS38 | V11: ='1. MPBC'!AQ40 | W11: ='1. MPBC'!AR40 | X11: =IFERROR(IF(G11="",IF(W11="",V11,W11),G11),"") | Y11: =IFERROR(IF(J11="",IF(I11="",H11,I11),J11),"")
A12: e | B12: ='1. MPBC'!AU10 -> Supplier 10 | C12: ='1. MPBC'!AU28 -> 0 | D12: =IFERROR(IF(U12="",IF(T12="",S12,T12),U12),"") | E12: ='1. MPBC'!AW20 -> <-- select country | F12: ='1. MPBC'!$D$28 -> 0 | G12: ='1. MPBC'!AW40 | H12: ='1. MPBC'!AU39 | I12: ='1. MPBC'!AV39 | J12: ='1. MPBC'!AW39 | K12: =IF(J12=0,"",IFERROR(H12-J12,"")) | L12: =IF(I12=0,"",IFERROR(H12-I12,"")) | M12: =IF(J12=0,"",IFERROR(I12-J12,"")) | N12: =IFERROR(K12/H12,"") | O12: =IFERROR(L12/H12,"") | P12: =IFERROR(M12/I12,"") | Q12: =IFERROR($C$14-J12,"") | R12: =IFERROR(Q12/$C$14,"") | S12: ='1. MPBC'!AU38 | T12: ='1. MPBC'!AV38 | U12: ='1. MPBC'!AW38 | V12: ='1. MPBC'!AU40 | W12: ='1. MPBC'!AV40 | X12: =IFERROR(IF(G12="",IF(W12="",V12,W12),G12),"") | Y12: =IFERROR(IF(J12="",IF(I12="",H12,I12),J12),"")
A13: r | B13: 1 | C13: 2 | D13: 3 | E13: 4 | F13: 5 | G13: 6 | H13: 7 | I13: 8 | J13: 9 | K13: 10 | L13: 11 | M13: 12 | N13: 13 | O13: 14 | P13: 15 | Q13: 16 | R13: 17 | S13: 18 | T13: 19 | U13: 20 | V13: 21 | W13: 22 | X13: 23 | Y13: 24
A14: s | B14: RAS value: | C14: ='1. MPBC'!M6 -> 0 | G14: Preferred source L1
A15: i | G15: Second Source
A16: o | B16: do not touch anything here! | G16: not preferred Source
A17: n
A18: - | G18: Yes
A19: 1 | G19: No
A20: .
A21: 0
B23: Country | C23: Chariman Region
B24: Argentina | C24: COA
B25: Australia | C25: COSEA
B26: Brazil | C26: COA
B27: China | C27: COC
B28: Croatia | C28: COE
B29: Czech Republic | C29: COE
B30: Estonia | C30: COE
B31: Finland | C31: COE
B32: France | C32: COE
B33: Germany | C33: COE
B34: Hungary | C34: COE
... B59: other | C59: not defined

Sheet 1. MPBC
B2: #VALUE! | G2: Form_GSP_MPBC_00001_2025_09
B3: Motherson Purchase BID Comparison [MPBC]
B4: Project Detail | G4: Receive Date @ GSP | K4: Requisition Type | M4: Capex [Motherson budget] | O4: RAS Category L1 | Q4: =IFERROR(IF(VLOOKUP($M$8,#REF!,2,FALSE)="", "-", VLOOKUP($M$8,#REF!,2,FALSE)),"check Com.code / country") -> check Com.code / country | T4: Benchmark
G5: Approval Date @ GSP | K5: days @ GSP | M5: =IFERROR(IF(I5="","",IF(I4="","",I5-I4)),"") | O5: RAS Category L2 | Q5: =IFERROR(IF(VLOOKUP($M$8,#REF!,3,FALSE)="", "-", VLOOKUP($M$8,#REF!,3,FALSE)),"check Com.code / country") -> check Com.code / country
B6: RAS Number | G6: Region | I6: =IFERROR(VLOOKUP(I9,calc!B24:C59,2,FALSE),"select country") -> select country | K6: ="RAS Value in "&D28 -> RAS Value in | O6: RAS Category L3 | Q6: =IFERROR(IF(VLOOKUP($M$8,#REF!,4,FALSE)="", "-", VLOOKUP($M$8,#REF!,4,FALSE)),"check Com.code / country") -> check Com.code / country
B7: Sheet No. | G7: Group Company | K7: Unit Negotiated Value | M7: =IFERROR(VLOOKUP(G66,calc!B2:J12,8,FALSE),"") | O7: RAS Category L4 | Q7: =IFERROR(IF(VLOOKUP($M$8,#REF!,5,FALSE)="", "-", VLOOKUP($M$8,#REF!,5,FALSE)),"check Com.code / country") -> check Com.code / country
B8: Indenter, Originator or RFQ Responsible | G8: Plant / Unit | K8: Com. Code / Category | O8: RAS Category L5 | Q8: =IFERROR(IF(VLOOKUP($M$8,#REF!,6,FALSE)="", "-", VLOOKUP($M$8,#REF!,6,FALSE)),"check Com.code / country") -> check Com.code / country | T8: last PO
B9: Contact Number | G9: Country | K9: GSP Manager | M9: =IFERROR(IF(I9="India",IF(VLOOKUP($M$8,#REF!,9,FALSE)="","-",VLOOKUP($M$8,#REF!,9,FALSE)),IF(VLOOKUP($M$8,#REF!,8,FALSE)="","-",VLOOKUP($M$8,#REF!,8,FALSE))),"check Com.code / country") -> check Com.code / country | O9: RAS Category L6 | Q9: =IFERROR(IF(VLOOKUP($M$8,#REF!,7,FALSE)="", "-", VLOOKUP($M$8,#REF!,7,FALSE)),"check Com.code / country") -> check Com.code / country
B10: Name of the Supplier | G10: Supplier 1 | K10: Supplier 2 | O10: Supplier 3 | T10: Benchmark | W10: Supplier 4 | AA10: Supplier 5 | AE10: Supplier 6 | AI10: Supplier 7 | AM10: Supplier 8 | AQ10: Supplier 9 | AU10: Supplier 10
B11: Preference
B12: Quote meet spec
B13: Supplier's Contact Person
B14: Supplier's Contact Number
B15: Supplier's Email Address
B16: Offer No.
B17: Offer Date
B18: Offer Validity
B19: Supplier Country / Classification | I19: =IFERROR(VLOOKUP(G19,country_class!$B:$D,2,FALSE),"<-- select country") -> <-- select country | M19: =IFERROR(VLOOKUP(K19,country_class!$B:$D,2,FALSE),"<-- select country") -> <-- select country | Q19: =IFERROR(VLOOKUP(O19,country_class!$B:$D,2,FALSE),"<-- select country") -> <-- select country | U19: =IFERROR(VLOOKUP(T19,country_class!$B:$D,2,FALSE),"<-- select") -> <-- select | Y19: =IFERROR(VLOOKUP(W19,country_class!$B:$D,2,FALSE),"<-- select country") -> <-- select country | AC19: =IFERROR(VLOOKUP(AA19,country_class!$B:$D,2,FALSE),"<-- select country") -> <-- select country | AG19: =IFERROR(VLOOKUP(AE19,country_class!$B:$D,2,FALSE),"<-- select country") -> <-- select country | AK19: =IFERROR(VLOOKUP(AI19,country_class!$B:$D,2,FALSE),"<-- select country") -> <-- select country | AO19: =IFERROR(VLOOKUP(AM19,country_class!$B:$D,2,FALSE),"<-- select country") -> <-- select country | AS19: =IFERROR(VLOOKUP(AQ19,country_class!$B:$D,2,FALSE),"<-- select country") -> <-- select country | AW19: =IFERROR(VLOOKUP(AU19,country_class!$B:$D,2,FALSE),"<-- select country") -> <-- select country
B20: Country of Origin / Classification | I20: =IFERROR(VLOOKUP(G20,country_class!$B:$D,2,FALSE),"<-- select country") -> <-- select country | M20: =IFERROR(VLOOKUP(K20,country_class!$B:$D,2,FALSE),"<-- select country") -> <-- select country | Q20: =IFERROR(VLOOKUP(O20,country_class!$B:$D,2,FALSE),"<-- select country") -> <-- select country | U20: =IFERROR(VLOOKUP(T20,country_class!$B:$D,2,FALSE),"<-- select") -> <-- select | Y20: =IFERROR(VLOOKUP(W20,country_class!$B:$D,2,FALSE),"<-- select country") -> <-- select country | AC20: =IFERROR(VLOOKUP(AA20,country_class!$B:$D,2,FALSE),"<-- select country") -> <-- select country | AG20: =IFERROR(VLOOKUP(AE20,country_class!$B:$D,2,FALSE),"<-- select country") -> <-- select country | AK20: =IFERROR(VLOOKUP(AI20,country_class!$B:$D,2,FALSE),"<-- select country") -> <-- select country | AO20: =IFERROR(VLOOKUP(AM20,country_class!$B:$D,2,FALSE),"<-- select country") -> <-- select country | AS20: =IFERROR(VLOOKUP(AQ20,country_class!$B:$D,2,FALSE),"<-- select country") -> <-- select country | AW20: =IFERROR(VLOOKUP(AU20,country_class!$B:$D,2,FALSE),"<-- select country") -> <-- select country
B21: Financial Risk (RAPID RATING or others)
B22: Panel supplier status
B23: ISO 9001
B24: ISO 14001
B25: ECOVADIS rating
B26: TISAX
B27: Supplier rating / Risk assessment (sheet "Supp x risk") | G27: ='Supp 1 risk'!D6 -> 0 | K27: ='Supp 2 risk'!D6 -> 0 | O27: ='Supp 3 risk'!D6 -> 0 | W27: ='Supp 4 risk'!D6 -> 0 | AA27: ='Supp 5 risk'!D6 -> 0 | AE27: ='Supp 6 risk'!D6 -> 0 | AI27: ='Supp 7 risk'!D6 -> 0 | AM27: ='Supp 8 risk'!D6 -> 0 | AQ27: ='Supp 9 risk'!D6 -> 0 | AU27: ='Supp 10 risk'!D6 -> 0
B28: Currency for Comparison: | E28: Supplier Currency | I28: =IF(G28="","<-- select currency",IF($D$28="","Select curr in D28",IFERROR(VLOOKUP(G28,'6. exchange_rates'!$C$3:$E$35,3,FALSE)/VLOOKUP($D$28,'6. exchange_rates'!$C$3:$E$35,3,FALSE),"<-- select currency"))) -> <-- select currency | M28: =IF(K28="","<-- select currency",IF($D$28="","Select curr in D28",IFERROR(VLOOKUP(K28,'6. exchange_rates'!$C$3:$E$35,3,FALSE)/VLOOKUP($D$28,'6. exchange_rates'!$C$3:$E$35,3,FALSE),"<-- select currency"))) -> <-- select currency | Q28: =IF(O28="","<-- select currency",IF($D$28="","Select curr in D28",IFERROR(VLOOKUP(O28,'6. exchange_rates'!$C$3:$E$35,3,FALSE)/VLOOKUP($D$28,'6. exchange_rates'!$C$3:$E$35,3,FALSE),"<-- select currency"))) -> <-- select currency | U28: =IF(T28="","<-- select currency",IF($D$28="","Select curr in D28",IFERROR(VLOOKUP(T28,'6. exchange_rates'!$C$3:$E$35,3,FALSE)/VLOOKUP($D$28,'6. exchange_rates'!$C$3:$E$35,3,FALSE),"<-- select currency"))) -> <-- select currency | Y28: =IF(W28="","<-- select currency",IF($D$28="","Select curr in D28",IFERROR(VLOOKUP(W28,'6. exchange_rates'!$C$3:$E$35,3,FALSE)/VLOOKUP($D$28,'6. exchange_rates'!$C$3:$E$35,3,FALSE),"<-- select currency"))) -> <-- select currency | AC28: =IF(AA28="","<-- select currency",IF($D$28="","Select curr in D28",IFERROR(VLOOKUP(AA28,'6. exchange_rates'!$C$3:$E$35,3,FALSE)/VLOOKUP($D$28,'6. exchange_rates'!$C$3:$E$35,3,FALSE),"<-- select currency"))) -> <-- select currency | AG28: =IF(AE28="","<-- select currency",IF($D$28="","Select curr in D28",IFERROR(VLOOKUP(AE28,'6. exchange_rates'!$C$3:$E$35,3,FALSE)/VLOOKUP($D$28,'6. exchange_rates'!$C$3:$E$35,3,FALSE),"<-- select currency"))) -> <-- select currency | AK28: =IF(AI28="","<-- select currency",IF($D$28="","Select curr in D28",IFERROR(VLOOKUP(AI28,'6. exchange_rates'!$C$3:$E$35,3,FALSE)/VLOOKUP($D$28,'6. exchange_rates'!$C$3:$E$35,3,FALSE),"<-- select currency"))) -> <-- select currency | AO28: =IF(AM28="","<-- select currency",IF($D$28="","Select curr in D28",IFERROR(VLOOKUP(AM28,'6. exchange_rates'!$C$3:$E$35,3,FALSE)/VLOOKUP($D$28,'6. exchange_rates'!$C$3:$E$35,3,FALSE),"<-- select currency"))) -> <-- select currency | AS28: =IF(AQ28="","<-- select currency",IF($D$28="","Select curr in D28",IFERROR(VLOOKUP(AQ28,'6. exchange_rates'!$C$3:$E$35,3,FALSE)/VLOOKUP($D$28,'6. exchange_rates'!$C$3:$E$35,3,FALSE),"<-- select currency"))) -> <-- select currency | AW28: =IF(AU28="","<-- select currency",IF($D$28="","Select curr in D28",IFERROR(VLOOKUP(AU28,'6. exchange_rates'!$C$3:$E$35,3,FALSE)/VLOOKUP($D$28,'6. exchange_rates'!$C$3:$E$35,3,FALSE),"<-- select currency"))) -> <-- select currency
B29: Description | D29: Make / Brand | E29: UOM | F29: Qty | G29: Initial Offer (Unit) | H29: Revised Offer (Unit) | I29: Final Offer (GSP) | J29: Final Amount | K29: Initial Offer (Unit) | L29: Revised Offer (Unit) | M29: Final Offer (GSP) | N29: Final Amount | O29: Initial Offer (Unit) | P29: Revised Offer (Unit) | Q29: Final Offer (GSP) | R29: Final Amount | T29: Final Offer | U29: Final Amount | W29: Initial Offer (Unit) | X29: Revised Offer (Unit) | Y29: Final Offer (GSP) | Z29: Final Amount | AA29: Initial Offer (Unit) | AB29: Revised Offer (Unit) | AC29: Final Offer (GSP) | AD29: Final Amount | AE29: Initial Offer (Unit) | AF29: Revised Offer (Unit) | AG29: Final Offer (GSP) | AH29: Final Amount | AI29: Initial Offer (Unit) | AJ29: Revised Offer (Unit) | AK29: Final Offer (GSP) | AL29: Final Amount | AM29: Initial Offer (Unit) | AN29: Revised Offer (Unit) | AO29: Final Offer (GSP) | AP29: Final Amount | AQ29: Initial Offer (Unit) | AR29: Revised Offer (Unit) | AS29: Final Offer (GSP) | AT29: Final Amount | AU29: Initial Offer (Unit) | AV29: Revised Offer (Unit) | AW29: Final Offer (GSP) | AX29: Final Amount
B30: 1 | J30: =IF($F30="", "", IF(AND(G30="", H30="", I30=""), "", $F30 * IF(I30<>"", I30, IF(H30<>"", H30, G30)))) | N30: =IF($F30="", "", IF(AND(K30="", L30="", M30=""), "", $F30 * IF(M30<>"", M30, IF(L30<>"", L30, K30)))) | R30: =IF($F30="", "", IF(AND(O30="", P30="", Q30=""), "", $F30 * IF(Q30<>"", Q30, IF(P30<>"", P30, O30)))) | U30: =IF(OR($F30=0, T30=""), "", T30*$F30) | Z30: =IF($F30="", "", IF(AND(W30="", X30="", Y30=""), "", $F30 * IF(Y30<>"", Y30, IF(X30<>"", X30, W30)))) | AD30: =IF($F30="", "", IF(AND(AA30="", AB30="", AC30=""), "", $F30 * IF(AC30<>"", AC30, IF(AB30<>"", AB30, AA30)))) | AH30: =IF($F30="", "", IF(AND(AE30="", AF30="", AG30=""), "", $F30 * IF(AG30<>"", AG30, IF(AF30<>"", AF30, AE30)))) | AL30: =IF($F30="", "", IF(AND(AI30="", AJ30="", AK30=""), "", $F30 * IF(AK30<>"", AK30, IF(AJ30<>"", AJ30, AI30)))) | AP30: =IF($F30="", "", IF(AND(AM30="", AN30="", AO30=""), "", $F30 * IF(AO30<>"", AO30, IF(AN30<>"", AN30, AM30)))) | AT30: =IF($F30="", "", IF(AND(AQ30="", AR30="", AS30=""), "", $F30 * IF(AS30<>"", AS30, IF(AR30<>"", AR30, AQ30)))) | AX30: =IF($F30="", "", IF(AND(AU30="", AV30="", AW30=""), "", $F30 * IF(AW30<>"", AW30, IF(AV30<>"", AV30, AU30))))
B31: 2 | J31: =IF($F31="", "", IF(AND(G31="", H31="", I31=""), "", $F31 * IF(I31<>"", I31, IF(H31<>"", H31, G31)))) | N31: =IF($F31="", "", IF(AND(K31="", L31="", M31=""), "", $F31 * IF(M31<>"", M31, IF(L31<>"", L31, K31)))) | R31: =IF($F31="", "", IF(AND(O31="", P31="", Q31=""), "", $F31 * IF(Q31<>"", Q31, IF(P31<>"", P31, O31)))) | U31: =IF(OR($F31=0, T31=""), "", T31*$F31) | Z31: =IF($F31="", "", IF(AND(W31="", X31="", Y31=""), "", $F31 * IF(Y31<>"", Y31, IF(X31<>"", X31, W31)))) | AD31: =IF($F31="", "", IF(AND(AA31="", AB31="", AC31=""), "", $F31 * IF(AC31<>"", AC31, IF(AB31<>"", AB31, AA31)))) | AH31: =IF($F31="", "", IF(AND(AE31="", AF31="", AG31=""), "", $F31 * IF(AG31<>"", AG31, IF(AF31<>"", AF31, AE31)))) | AL31: =IF($F31="", "", IF(AND(AI31="", AJ31="", AK31=""), "", $F31 * IF(AK31<>"", AK31, IF(AJ31<>"", AJ31, AI31)))) | AP31: =IF($F31="", "", IF(AND(AM31="", AN31="", AO31=""), "", $F31 * IF(AO31<>"", AO31, IF(AN31<>"", AN31, AM31)))) | AT31: =IF($F31="", "", IF(AND(AQ31="", AR31="", AS31=""), "", $F31 * IF(AS31<>"", AS31, IF(AR31<>"", AR31, AQ31)))) | AX31: =IF($F31="", "", IF(AND(AU31="", AV31="", AW31=""), "", $F31 * IF(AW31<>"", AW31, IF(AV31<>"", AV31, AU31))))
B32: 3 | J32: =IF($F32="", "", IF(AND(G32="", H32="", I32=""), "", $F32 * IF(I32<>"", I32, IF(H32<>"", H32, G32)))) | N32: =IF($F32="", "", IF(AND(K32="", L32="", M32=""), "", $F32 * IF(M32<>"", M32, IF(L32<>"", L32, K32)))) | R32: =IF($F32="", "", IF(AND(O32="", P32="", Q32=""), "", $F32 * IF(Q32<>"", Q32, IF(P32<>"", P32, O32)))) | U32: =IF(OR($F32=0, T32=""), "", T32*$F32) | Z32: =IF($F32="", "", IF(AND(W32="", X32="", Y32=""), "", $F32 * IF(Y32<>"", Y32, IF(X32<>"", X32, W32)))) | AD32: =IF($F32="", "", IF(AND(AA32="", AB32="", AC32=""), "", $F32 * IF(AC32<>"", AC32, IF(AB32<>"", AB32, AA32)))) | AH32: =IF($F32="", "", IF(AND(AE32="", AF32="", AG32=""), "", $F32 * IF(AG32<>"", AG32, IF(AF32<>"", AF32, AE32)))) | AL32: =IF($F32="", "", IF(AND(AI32="", AJ32="", AK32=""), "", $F32 * IF(AK32<>"", AK32, IF(AJ32<>"", AJ32, AI32)))) | AP32: =IF($F32="", "", IF(AND(AM32="", AN32="", AO32=""), "", $F32 * IF(AO32<>"", AO32, IF(AN32<>"", AN32, AM32)))) | AT32: =IF($F32="", "", IF(AND(AQ32="", AR32="", AS32=""), "", $F32 * IF(AS32<>"", AS32, IF(AR32<>"", AR32, AQ32)))) | AX32: =IF($F32="", "", IF(AND(AU32="", AV32="", AW32=""), "", $F32 * IF(AW32<>"", AW32, IF(AV32<>"", AV32, AU32))))
B33: 4 | J33: =IF($F33="", "", IF(AND(G33="", H33="", I33=""), "", $F33 * IF(I33<>"", I33, IF(H33<>"", H33, G33)))) | N33: =IF($F33="", "", IF(AND(K33="", L33="", M33=""), "", $F33 * IF(M33<>"", M33, IF(L33<>"", L33, K33)))) | R33: =IF($F33="", "", IF(AND(O33="", P33="", Q33=""), "", $F33 * IF(Q33<>"", Q33, IF(P33<>"", P33, O33)))) | U33: =IF(OR($F33=0, T33=""), "", T33*$F33) | Z33: =IF($F33="", "", IF(AND(W33="", X33="", Y33=""), "", $F33 * IF(Y33<>"", Y33, IF(X33<>"", X33, W33)))) | AD33: =IF($F33="", "", IF(AND(AA33="", AB33="", AC33=""), "", $F33 * IF(AC33<>"", AC33, IF(AB33<>"", AB33, AA33)))) | AH33: =IF($F33="", "", IF(AND(AE33="", AF33="", AG33=""), "", $F33 * IF(AG33<>"", AG33, IF(AF33<>"", AF33, AE33)))) | AL33: =IF($F33="", "", IF(AND(AI33="", AJ33="", AK33=""), "", $F33 * IF(AK33<>"", AK33, IF(AJ33<>"", AJ33, AI33)))) | AP33: =IF($F33="", "", IF(AND(AM33="", AN33="", AO33=""), "", $F33 * IF(AO33<>"", AO33, IF(AN33<>"", AN33, AM33)))) | AT33: =IF($F33="", "", IF(AND(AQ33="", AR33="", AS33=""), "", $F33 * IF(AS33<>"", AS33, IF(AR33<>"", AR33, AQ33)))) | AX33: =IF($F33="", "", IF(AND(AU33="", AV33="", AW33=""), "", $F33 * IF(AW33<>"", AW33, IF(AV33<>"", AV33, AU33))))
B34: 5 | J34: =IF($F34="", "", IF(AND(G34="", H34="", I34=""), "", $F34 * IF(I34<>"", I34, IF(H34<>"", H34, G34)))) | N34: =IF($F34="", "", IF(AND(K34="", L34="", M34=""), "", $F34 * IF(M34<>"", M34, IF(L34<>"", L34, K34)))) | R34: =IF($F34="", "", IF(AND(O34="", P34="", Q34=""), "", $F34 * IF(Q34<>"", Q34, IF(P34<>"", P34, O34)))) | U34: =IF(OR($F34=0, T34=""), "", T34*$F34) | Z34: =IF($F34="", "", IF(AND(W34="", X34="", Y34=""), "", $F34 * IF(Y34<>"", Y34, IF(X34<>"", X34, W34)))) | AD34: =IF($F34="", "", IF(AND(AA34="", AB34="", AC34=""), "", $F34 * IF(AC34<>"", AC34, IF(AB34<>"", AB34, AA34)))) | AH34: =IF($F34="", "", IF(AND(AE34="", AF34="", AG34=""), "", $F34 * IF(AG34<>"", AG34, IF(AF34<>"", AF34, AE34)))) | AL34: =IF($F34="", "", IF(AND(AI34="", AJ34="", AK34=""), "", $F34 * IF(AK34<>"", AK34, IF(AJ34<>"", AJ34, AI34)))) | AP34: =IF($F34="", "", IF(AND(AM34="", AN34="", AO34=""), "", $F34 * IF(AO34<>"", AO34, IF(AN34<>"", AN34, AM34)))) | AT34: =IF($F34="", "", IF(AND(AQ34="", AR34="", AS34=""), "", $F34 * IF(AS34<>"", AS34, IF(AR34<>"", AR34, AQ34)))) | AX34: =IF($F34="", "", IF(AND(AU34="", AV34="", AW34=""), "", $F34 * IF(AW34<>"", AW34, IF(AV34<>"", AV34, AU34))))
B35: 6 | J35: =IF($F35="", "", IF(AND(G35="", H35="", I35=""), "", $F35 * IF(I35<>"", I35, IF(H35<>"", H35, G35)))) | N35: =IF($F35="", "", IF(AND(K35="", L35="", M35=""), "", $F35 * IF(M35<>"", M35, IF(L35<>"", L35, K35)))) | R35: =IF($F35="", "", IF(AND(O35="", P35="", Q35=""), "", $F35 * IF(Q35<>"", Q35, IF(P35<>"", P35, O35)))) | U35: =IF(OR($F35=0, T35=""), "", T35*$F35) | Z35: =IF($F35="", "", IF(AND(W35="", X35="", Y35=""), "", $F35 * IF(Y35<>"", Y35, IF(X35<>"", X35, W35)))) | AD35: =IF($F35="", "", IF(AND(AA35="", AB35="", AC35=""), "", $F35 * IF(AC35<>"", AC35, IF(AB35<>"", AB35, AA35)))) | AH35: =IF($F35="", "", IF(AND(AE35="", AF35="", AG35=""), "", $F35 * IF(AG35<>"", AG35, IF(AF35<>"", AF35, AE35)))) | AL35: =IF($F35="", "", IF(AND(AI35="", AJ35="", AK35=""), "", $F35 * IF(AK35<>"", AK35, IF(AJ35<>"", AJ35, AI35)))) | AP35: =IF($F35="", "", IF(AND(AM35="", AN35="", AO35=""), "", $F35 * IF(AO35<>"", AO35, IF(AN35<>"", AN35, AM35)))) | AT35: =IF($F35="", "", IF(AND(AQ35="", AR35="", AS35=""), "", $F35 * IF(AS35<>"", AS35, IF(AR35<>"", AR35, AQ35)))) | AX35: =IF($F35="", "", IF(AND(AU35="", AV35="", AW35=""), "", $F35 * IF(AW35<>"", AW35, IF(AV35<>"", AV35, AU35))))
B36: 7 | J36: =IF($F36="", "", IF(AND(G36="", H36="", I36=""), "", $F36 * IF(I36<>"", I36, IF(H36<>"", H36, G36)))) | N36: =IF($F36="", "", IF(AND(K36="", L36="", M36=""), "", $F36 * IF(M36<>"", M36, IF(L36<>"", L36, K36)))) | R36: =IF($F36="", "", IF(AND(O36="", P36="", Q36=""), "", $F36 * IF(Q36<>"", Q36, IF(P36<>"", P36, O36)))) | U36: =IF(OR($F36=0, T36=""), "", T36*$F36) | Z36: =IF($F36="", "", IF(AND(W36="", X36="", Y36=""), "", $F36 * IF(Y36<>"", Y36, IF(X36<>"", X36, W36)))) | AD36: =IF($F36="", "", IF(AND(AA36="", AB36="", AC36=""), "", $F36 * IF(AC36<>"", AC36, IF(AB36<>"", AB36, AA36)))) | AH36: =IF($F36="", "", IF(AND(AE36="", AF36="", AG36=""), "", $F36 * IF(AG36<>"", AG36, IF(AF36<>"", AF36, AE36)))) | AL36: =IF($F36="", "", IF(AND(AI36="", AJ36="", AK36=""), "", $F36 * IF(AK36<>"", AK36, IF(AJ36<>"", AJ36, AI36)))) | AP36: =IF($F36="", "", IF(AND(AM36="", AN36="", AO36=""), "", $F36 * IF(AO36<>"", AO36, IF(AN36<>"", AN36, AM36)))) | AT36: =IF($F36="", "", IF(AND(AQ36="", AR36="", AS36=""), "", $F36 * IF(AS36<>"", AS36, IF(AR36<>"", AR36, AQ36)))) | AX36: =IF($F36="", "", IF(AND(AU36="", AV36="", AW36=""), "", $F36 * IF(AW36<>"", AW36, IF(AV36<>"", AV36, AU36))))
B37: 8 | J37: =IF($F37="", "", IF(AND(G37="", H37="", I37=""), "", $F37 * IF(I37<>"", I37, IF(H37<>"", H37, G37)))) | N37: =IF($F37="", "", IF(AND(K37="", L37="", M37=""), "", $F37 * IF(M37<>"", M37, IF(L37<>"", L37, K37)))) | R37: =IF($F37="", "", IF(AND(O37="", P37="", Q37=""), "", $F37 * IF(Q37<>"", Q37, IF(P37<>"", P37, O37)))) | U37: =IF(OR($F37=0, T37=""), "", T37*$F37) | Z37: =IF($F37="", "", IF(AND(W37="", X37="", Y37=""), "", $F37 * IF(Y37<>"", Y37, IF(X37<>"", X37, W37)))) | AD37: =IF($F37="", "", IF(AND(AA37="", AB37="", AC37=""), "", $F37 * IF(AC37<>"", AC37, IF(AB37<>"", AB37, AA37)))) | AH37: =IF($F37="", "", IF(AND(AE37="", AF37="", AG37=""), "", $F37 * IF(AG37<>"", AG37, IF(AF37<>"", AF37, AE37)))) | AL37: =IF($F37="", "", IF(AND(AI37="", AJ37="", AK37=""), "", $F37 * IF(AK37<>"", AK37, IF(AJ37<>"", AJ37, AI37)))) | AP37: =IF($F37="", "", IF(AND(AM37="", AN37="", AO37=""), "", $F37 * IF(AO37<>"", AO37, IF(AN37<>"", AN37, AM37)))) | AT37: =IF($F37="", "", IF(AND(AQ37="", AR37="", AS37=""), "", $F37 * IF(AS37<>"", AS37, IF(AR37<>"", AR37, AQ37)))) | AX37: =IF($F37="", "", IF(AND(AU37="", AV37="", AW37=""), "", $F37 * IF(AW37<>"", AW37, IF(AV37<>"", AV37, AU37))))
B38: Total Amount in supplier currency | G38: {=IF(AND(ISBLANK(G30:G37)),"",SUMPRODUCT(G30:G37,$F$30:$F$37))} | H38: {=IF(AND(ISBLANK(H30:H37)),"",SUMPRODUCT(H30:H37,$F$30:$F$37))} | I38: {=IF(AND(ISBLANK(I30:I37)),"",SUMPRODUCT(I30:I37,$F$30:$F$37))} | K38: {=IF(AND(ISBLANK(K30:K37)),"",SUMPRODUCT(K30:K37,$F$30:$F$37))} | L38: {=IF(AND(ISBLANK(L30:L37)),"",SUMPRODUCT(L30:L37,$F$30:$F$37))} | M38: {=IF(AND(ISBLANK(M30:M37)),"",SUMPRODUCT(M30:M37,$F$30:$F$37))} | O38: {=IF(AND(ISBLANK(O30:O37)),"",SUMPRODUCT(O30:O37,$F$30:$F$37))} | P38: {=IF(AND(ISBLANK(P30:P37)),"",SUMPRODUCT(P30:P37,$F$30:$F$37))} | Q38: {=IF(AND(ISBLANK(Q30:Q37)),"",SUMPRODUCT(Q30:Q37,$F$30:$F$37))} | T38: =IF(T30="","",SUMPRODUCT(T30:T37,$F$30:$F$37)) | W38: {=IF(AND(ISBLANK(W30:W37)),"",SUMPRODUCT(W30:W37,$F$30:$F$37))} | X38: {=IF(AND(ISBLANK(X30:X37)),"",SUMPRODUCT(X30:X37,$F$30:$F$37))} | Y38: {=IF(AND(ISBLANK(Y30:Y37)),"",SUMPRODUCT(Y30:Y37,$F$30:$F$37))} | AA38: {=IF(AND(ISBLANK(AA30:AA37)),"",SUMPRODUCT(AA30:AA37,$F$30:$F$37))} | AB38: {=IF(AND(ISBLANK(AB30:AB37)),"",SUMPRODUCT(AB30:AB37,$F$30:$F$37))} | AC38: {=IF(AND(ISBLANK(AC30:AC37)),"",SUMPRODUCT(AC30:AC37,$F$30:$F$37))} | AE38: {=IF(AND(ISBLANK(AE30:AE37)),"",SUMPRODUCT(AE30:AE37,$F$30:$F$37))} | AF38: {=IF(AND(ISBLANK(AF30:AF37)),"",SUMPRODUCT(AF30:AF37,$F$30:$F$37))} | AG38: {=IF(AND(ISBLANK(AG30:AG37)),"",SUMPRODUCT(AG30:AG37,$F$30:$F$37))} | AI38: {=IF(AND(ISBLANK(AI30:AI37)),"",SUMPRODUCT(AI30:AI37,$F$30:$F$37))} | AJ38: {=IF(AND(ISBLANK(AJ30:AJ37)),"",SUMPRODUCT(AJ30:AJ37,$F$30:$F$37))} | AK38: {=IF(AND(ISBLANK(AK30:AK37)),"",SUMPRODUCT(AK30:AK37,$F$30:$F$37))} | AM38: {=IF(AND(ISBLANK(AM30:AM37)),"",SUMPRODUCT(AM30:AM37,$F$30:$F$37))} | AN38: {=IF(AND(ISBLANK(AN30:AN37)),"",SUMPRODUCT(AN30:AN37,$F$30:$F$37))} | AO38: {=IF(AND(ISBLANK(AO30:AO37)),"",SUMPRODUCT(AO30:AO37,$F$30:$F$37))} | AQ38: {=IF(AND(ISBLANK(AQ30:AQ37)),"",SUMPRODUCT(AQ30:AQ37,$F$30:$F$37))} | AR38: {=IF(AND(ISBLANK(AR30:AR37)),"",SUMPRODUCT(AR30:AR37,$F$30:$F$37))} | AS38: {=IF(AND(ISBLANK(AS30:AS37)),"",SUMPRODUCT(AS30:AS37,$F$30:$F$37))} | AU38: {=IF(AND(ISBLANK(AU30:AU37)),"",SUMPRODUCT(AU30:AU37,$F$30:$F$37))} | AV38: {=IF(AND(ISBLANK(AV30:AV37)),"",SUMPRODUCT(AV30:AV37,$F$30:$F$37))} | AW38: {=IF(AND(ISBLANK(AW30:AW37)),"",SUMPRODUCT(AW30:AW37,$F$30:$F$37))}
B39: ="Total Amount in "&D28 -> Total Amount in | G39: =IFERROR(IF(G38="","",G38*I28),) | H39: =IFERROR(H38*I28,"") | I39: =IFERROR(I38*I28,"") | K39: =IFERROR(IF(K38="","",K38*M28),) | L39: =IFERROR(L38*M28,"") | M39: =IFERROR(M38*M28,"") | O39: =IFERROR(IF(O38="","",O38*Q28),) | P39: =IFERROR(P38*Q28,"") | Q39: =IFERROR(Q38*Q28,"") | T39: =IFERROR(IF(T38="","",T38*U28),) | W39: =IFERROR(IF(W38="","",W38*Y28),) | X39: =IFERROR(X38*Y28,"") | Y39: =IFERROR(Y38*Y28,"") | AA39: =IFERROR(IF(AA38="","",AA38*AC28),) | AB39: =IFERROR(AB38*AC28,"") | AC39: =IFERROR(AC38*AC28,"") | AE39: =IFERROR(IF(AE38="","",AE38*AG28),) | AF39: =IFERROR(AF38*AG28,"") | AG39: =IFERROR(AG38*AG28,"") | AI39: =IFERROR(IF(AI38="","",AI38*AK28),) | AJ39: =IFERROR(AJ38*AK28,"") | AK39: =IFERROR(AK38*AK28,"") | AM39: =IFERROR(IF(AM38="","",AM38*AO28),) | AN39: =IFERROR(AN38*AO28,"") | AO39: =IFERROR(AO38*AO28,"") | AQ39: =IFERROR(IF(AQ38="","",AQ38*AS28),) | AR39: =IFERROR(AR38*AS28,"") | AS39: =IFERROR(AS38*AS28,"") | AU39: =IFERROR(IF(AU38="","",AU38*AW28),) | AV39: =IFERROR(AV38*AW28,"") | AW39: =IFERROR(AW38*AW28,"")
B40: ="Landed Cost (for Reference) in "&D28 -> Landed Cost (for Reference) in | G40: {=IF(G39="","",SUMPRODUCT(IF(ISNUMBER(G51:G57), G51:G57, 0)*I28)+G39)} | H40: {=IFERROR(SUMPRODUCT(IF(ISNUMBER(G51:G57), G51:G57, 0)*I28)+H39,"")} | I40: {=IFERROR(SUMPRODUCT(IF(ISNUMBER(I51:I57), I51:I57, 0)*I28)+I39,"")} | K40: {=IF(K39="","",SUMPRODUCT(IF(ISNUMBER(K51:K57), K51:K57, 0)*M28)+K39)} | L40: {=IFERROR(SUMPRODUCT(IF(ISNUMBER(K51:K57), K51:K57, 0)*M28)+L39,"")} | M40: {=IFERROR(SUMPRODUCT(IF(ISNUMBER(M51:M57), M51:M57, 0)*M28)+M39,"")} | O40: {=IF(O39="","",SUMPRODUCT(IF(ISNUMBER(O51:O57), O51:O57, 0)*Q28)+O39)} | P40: {=IFERROR(SUMPRODUCT(IF(ISNUMBER(O51:O57), O51:O57, 0)*Q28)+P39,"")} | Q40: {=IFERROR(SUMPRODUCT(IF(ISNUMBER(Q51:Q57), Q51:Q57, 0)*Q28)+Q39,"")} | T40: {=IF(T39="","",SUMPRODUCT(IF(ISNUMBER(T51:U57), T51:U57, 0)*U28)+T39)} | W40: {=IF(W39="","",SUMPRODUCT(IF(ISNUMBER(W51:W57), W51:W57, 0)*Y28)+W39)} | X40: {=IFERROR(SUMPRODUCT(IF(ISNUMBER(W51:W57), W51:W57, 0)*Y28)+X39,"")} | Y40: {=IFERROR(SUMPRODUCT(IF(ISNUMBER(Y51:Y57), Y51:Y57, 0)*Y28)+Y39,"")} | AA40: {=IF(AA39="","",SUMPRODUCT(IF(ISNUMBER(AA51:AA57), AA51:AA57, 0)*AC28)+AA39)} | AB40: {=IFERROR(SUMPRODUCT(IF(ISNUMBER(AA51:AA57), AA51:AA57, 0)*AC28)+AB39,"")} | AC40: {=IFERROR(SUMPRODUCT(IF(ISNUMBER(AC51:AC57), AC51:AC57, 0)*AC28)+AC39,"")} | AE40: {=IF(AE39="","",SUMPRODUCT(IF(ISNUMBER(AE51:AE57), AE51:AE57, 0)*AG28)+AE39)} | AF40: {=IFERROR(SUMPRODUCT(IF(ISNUMBER(AE51:AE57), AE51:AE57, 0)*AG28)+AF39,"")} | AG40: {=IFERROR(SUMPRODUCT(IF(ISNUMBER(AG51:AG57), AG51:AG57, 0)*AG28)+AG39,"")} | AI40: {=IF(AI39="","",SUMPRODUCT(IF(ISNUMBER(AI51:AI57), AI51:AI57, 0)*AK28)+AI39)} | AJ40: {=IFERROR(SUMPRODUCT(IF(ISNUMBER(AI51:AI57), AI51:AI57, 0)*AK28)+AJ39,"")} | AK40: {=IFERROR(SUMPRODUCT(IF(ISNUMBER(AK51:AK57), AK51:AK57, 0)*AK28)+AK39,"")} | AM40: {=IF(AM39="","",SUMPRODUCT(IF(ISNUMBER(AM51:AM57), AM51:AM57, 0)*AO28)+AM39)} | AN40: {=IFERROR(SUMPRODUCT(IF(ISNUMBER(AM51:AM57), AM51:AM57, 0)*AO28)+AN39,"")} | AO40: {=IFERROR(SUMPRODUCT(IF(ISNUMBER(AO51:AO57), AO51:AO57, 0)*AO28)+AO39,"")} | AQ40: {=IF(AQ39="","",SUMPRODUCT(IF(ISNUMBER(AQ51:AQ57), AQ51:AQ57, 0)*AS28)+AQ39)} | AR40: {=IFERROR(SUMPRODUCT(IF(ISNUMBER(AQ51:AQ57), AQ51:AQ57, 0)*AS28)+AR39,"")} | AS40: {=IFERROR(SUMPRODUCT(IF(ISNUMBER(AS51:AS57), AS51:AS57, 0)*AS28)+AS39,"")} | AU40: {=IF(AU39="","",SUMPRODUCT(IF(ISNUMBER(AU51:AU57), AU51:AU57, 0)*AW28)+AU39)} | AV40: {=IFERROR(SUMPRODUCT(IF(ISNUMBER(AU51:AU57), AU51:AU57, 0)*AW28)+AV39,"")} | AW40: {=IFERROR(SUMPRODUCT(IF(ISNUMBER(AW51:AW57), AW51:AW57, 0)*AW28)+AW39,"")}
F41: ="Saving Amount in "&D28 -> Saving Amount in | G41: =IFERROR(G39-I39,"") | H41: =IFERROR(G39-H39,"") | I41: =IFERROR(H39-I39,"") | K41: =IFERROR(K39-M39,"") | L41: =IFERROR(K39-L39,"") | M41: =IFERROR(L39-M39,"") | O41: =IFERROR(O39-Q39,"") | P41: =IFERROR(O39-P39,"") | Q41: =IFERROR(P39-Q39,"") | W41: =IFERROR(W39-Y39,"") | X41: =IFERROR(W39-X39,"") | Y41: =IFERROR(X39-Y39,"") | AA41: =IFERROR(AA39-AC39,"") | AB41: =IFERROR(AA39-AB39,"") | AC41: =IFERROR(AB39-AC39,"") | AE41: =IFERROR(AE39-AG39,"") | AF41: =IFERROR(AE39-AF39,"") | AG41: =IFERROR(AF39-AG39,"") | AI41: =IFERROR(AI39-AK39,"") | AJ41: =IFERROR(AI39-AJ39,"") | AK41: =IFERROR(AJ39-AK39,"") | AM41: =IFERROR(AM39-AO39,"") | AN41: =IFERROR(AM39-AN39,"") | AO41: =IFERROR(AN39-AO39,"") | AQ41: =IFERROR(AQ39-AS39,"") | AR41: =IFERROR(AQ39-AR39,"") | AS41: =IFERROR(AR39-AS39,"") | AU41: =IFERROR(AU39-AW39,"") | AV41: =IFERROR(AU39-AV39,"") | AW41: =IFERROR(AV39-AW39,"")
...

Sheet 3. BER - Bid exception report
A6: BID EXCEPTION REPORT
I7: Budget Line Ref.:
A8: Reasoning for not obtaining at least three bids/quotes | I8: Order Value:
A9: Reasoning for not obtaining one quote out of 3 from LCC Supliers/ from motherson interal company
A10: Reason for awarding the business to non L1 supplier
A11: (check one)
C13: A. | D13: There are less than three potential bidders. In this case two (2) bidders
D14: will be acceptable. The 3rd supplier declined mail to be attached.
D15: Explanatory notes/letters should be in the file for "No Bids."
C17: B. | D17: The item to be purchased is a sole-source item with no substitutes
D18: available (proprietary item).
C20: C. | D20: There are national or local supply contracts for the item(s) to be purchased
D21: and they are purchased from the contract supplier. (Reference Agreement)
C23: D. | D23: The item or items of similar nature have been purchased in the past six (6)
D24: months and the quotes from that purchase established the best supplier.
D25: Market conditions can change, so be cautious when exercising this option.
D26: (Reference previous order)
C28: E. | D28: Non L1 nomination / Other reasons
A30: Description of the product or service to be ordered:
A34: Justification of the product or service to be ordered:
A38: Justification for waiver of competitive bidding (attach additional information if required):
A43: Prepared by: | D43: Name: | G43: Signed: | I43: Date:
A46: Purchasing approval: | D46: Name: | G46: Signed: | I46: Date:
A49: Managing Director / COO / EVP approval: | D49: Name: | G49: Signed: | I49: Date:
A51: Approver comments:

Sheet 5. WCI calculation
I1: Explanation of the calculation (normally hidden)
B2: Currency | C2: ='1. MPBC'!G67
B3: Contract value: | C3: ='1. MPBC'!I67 | E3: averaged payment target extension: (days) | G3: =IF(J19=2,SUMPRODUCT(F9:F17,K9:K17)-SUMPRODUCT(D9:D17,J9:J17),"check %") -> 113 | I3: first date vs date in line | J3: first date vs date in line incl. Payment target (old terms) | K3: first date vs date in line incl. Payment target (new terms) | L3: Multiplication of days and percentages to be able to sum up (old terms) | M3: Multiplication of days and percentages to be able to sum up (new terms)
B4: Country/Region: | C4: India [INR] | E4: Working Capital Improvement: | G4: =IF(J19=2,C3*(G3/360),"check %") -> #VALUE!
B5: WACC: | C5: =VLOOKUP(C4,WACC!B3:D31,3,FALSE) -> 0.13 | E5: Valcon out of WCI: | G5: =IF(J19=2,C5*C3*(G3/360),"check %") -> #VALUE!
B7: steps | D7: initial payment terms | F7: final payment terms | P7: this file for calculating wci value yellow cells are to be adjusted up to 9 different steps are available on the bottom there is a line for checking if 100% is filled WCI is automatically calculated if there are any changes needed feel free to contact Felix Müller (felix.mueller@motherson.com)
B8: reason | C8: date | D8: percentage | E8: payment target | F8: percentage | G8: payment target
B9: down payment | C9: 44713 | D9: 0.3 | E9: 10 | I9: =IF(C9="","",C9-$C$9) -> 0 | J9: =IF(E9="","",$I9+E9) -> 10 | K9: =IF(G9="","",$I9+G9) | L9: =IF(J9="","",D9*J9) -> 3 | M9: =IF(K9="","",F9*K9)
B10: design approval | C10: 44870 | D10: 0.6 | E10: 10 | F10: 0.5 | G10: 100 | I10: =IF(C10="","",C10-$C$9) -> 157 | J10: =IF(E10="","",$I10+E10) -> 167 | K10: =IF(G10="","",$I10+G10) -> 257 | L10: =IF(J10="","",D10*J10) -> 100.2 | M10: =IF(K10="","",F10*K10) -> 128.5
B11: delivery | C11: 44896 | D11: 0.1 | E11: 10 | I11: =IF(C11="","",C11-$C$9) -> 183 | J11: =IF(E11="","",$I11+E11) -> 193 | K11: =IF(G11="","",$I11+G11) | L11: =IF(J11="","",D11*J11) -> 19.3 | M11: =IF(K11="","",F11*K11)
B12: installation | I12: =IF(C12="","",C12-$C$9) | J12: =IF(E12="","",$I12+E12) | K12: =IF(G12="","",$I12+G12) | L12: =IF(J12="","",D12*J12) | M12: =IF(K12="","",F12*K12)
B13: final approval | C13: 44927 | F13: 0.5 | G13: 0 | I13: =IF(C13="","",C13-$C$9) -> 214 | J13: =IF(E13="","",$I13+E13) | K13: =IF(G13="","",$I13+G13) -> 214 | L13: =IF(J13="","",D13*J13) | M13: =IF(K13="","",F13*K13) -> 107
B14: step 6 | I14: =IF(C14="","",C14-$C$9) | J14: =IF(E14="","",$I14+E14) | K14: =IF(G14="","",$I14+G14) | L14: =IF(J14="","",D14*J14) | M14: =IF(K14="","",F14*K14)
B15: step 7 | I15: =IF(C15="","",C15-$C$9) | J15: =IF(E15="","",$I15+E15) | K15: =IF(G15="","",$I15+G15) | L15: =IF(J15="","",D15*J15) | M15: =IF(K15="","",F15*K15)
B16: step 8 | I16: =IF(C16="","",C16-$C$9) | J16: =IF(E16="","",$I16+E16) | K16: =IF(G16="","",$I16+G16) | L16: =IF(J16="","",D16*J16) | M16: =IF(K16="","",F16*K16)
B17: step 9 | I17: =IF(C17="","",C17-$C$9) | J17: =IF(E17="","",$I17+E17) | K17: =IF(G17="","",$I17+G17) | L17: =IF(J17="","",D17*J17) | M17: =IF(K17="","",F17*K17)
B19: Check: | D19: =SUM(D9:D17) -> 1 | F19: =SUM(F9:F17) -> 1 | I19: =IF(D19=1,1,0) -> 1 | J19: =I19+K19 -> 2 | K19: =IF(F19=1,1,0) -> 1 | L19: =SUM(L9:L17) -> 122.5 | M19: =SUM(M9:M17) -> 235.5 | N19: =M19-L19 -> 113
I20: This cell checks if the sum of the percentages is 100 (old terms) | J20: This cell checks if correct values have been entered for both old and new percentages. | K20: This cell checks if the sum of the percentages is 100 (old terms) | L20: This value indicates after how many days a single payment would be made, which is the sum of the individual payment steps. (old terms) | M20: This value indicates after how many days a single payment would be made, which is the sum of the individual payment steps. (new terms) | N20: Difference between sum new and sum old = averaged payment target extension
B21: project: | C21: ='1. MPBC'!D4 -> 0
B22: supplier | C22: ='1. MPBC'!G66 -> 0
B23: project owner | C23: ='1. MPBC'!K66 -> 0
E25: Approval:

Sheet 6. exchange_rates
B2: Currency Name | C2: Code | D2: 1 EUR in XX | E2: 1 XX in EUR
B3: EURO | C3: EUR | D3: 1 | E3: =1/D3 -> 1 | F3: 1
B4: United States Dollar | C4: USD | D4: 1.16153 | E4: =1/D4 -> 0.86093342 | F4: 2
B5: Indian Rupee | C5: INR | D5: 101.82596 | E5: =1/D5 -> 0.0098206783 | F5: 3
B6: United Arab Emirates Dirham | C6: AED | D6: 4.26574 | E6: =1/D6 -> 0.23442591 | F6: 4
B7: Chinese Yuan | C7: CNY | D7: 8.34935 | E7: =1/D7 -> 0.1197698 | F7: 5
B8: Japanese Yen | C8: JPY | D8: 172.25902 | E8: =1/D8 -> 0.0058052112 | F8: 6
B9: Argentine Peso | C9: ARS | D9: 1534.6903 | E9: =1/D9 -> 0.00065159725 | F9: 7
B10: Australian Dollar | C10: AUD | D10: 1.78182 | E10: =1/D10 -> 0.56122392 | F10: 8
B11: Brazilian Real | C11: BRL | D11: 6.32166 | E11: =1/D11 -> 0.1581863 | F11: 9
B12: Swiss Franc | C12: CHF | D12: 0.94316 | E12: =1/D12 -> 1.0602655 | F12: 10
B13: Chinese Yuan | C13: CNY | D13: 8.34935 | E13: =1/D13 -> 0.1197698 | F13: 11
B14: British Pound Sterling | C14: GBP | D14: 0.86476 | E14: =1/D14 -> 1.1563902 | F14: 12
... B30: Czech Koruna | C30: CZK | D30: 24.3189 | E30: =1/D30 -> 0.041120281 | F30: 28
F31: 29
F32: 30
F33: 31
F34: 32
F35: 33
C36: * select *
B38: last update: | C38: 45881
B40: https://bankenverband.de/service/waehrungsrechner/table/
B41: https://themoneyconverter.com/DE

Sheet Supp 1 risk
B2: RISK CATEGORY GUIDELINES | F2: Score card
F3: Between | H3: Category | I3: Comment
B4: These guidelines are to help indicate the relative risk of a supply situation. If the situation does not clearly fit into a guideline / example, use common sense. | F4: 1 | G4: 10 | H4: Preferred | I4: Supplier can be considered for nomination
F5: 11 | G5: 16 | H5: Cautionary | I5: Supplier score to be understood to identify what has driven score and to work with supplier to improve before nomination
C6: Score | D6: =SUM(C13+C19+C25+C31+C37) -> 0 | F6: 17 | G6: 20 | H6: Risk | I6: Supplier score to be understood to identify what has driven score and to work with supplier to improve for future potential business but cannot be nominated
B7: Risk / Category | C7: Rating (1-5) | D7: Guidelines | E7: Comment | F7: 21 | G7: 50 | H7: High risk | I7: Supplier cannot to be sourced
B8: 1. Supplier location | C8: 1 | D8: Incumbent supplier located within 25 miles to motherson site
C9: 2 | D9: Incumbent supplier and located over 25miles from motherson site
C10: 3 | D10: New supplier located within 25 miles to motherson site
C11: 4 | D11: New supplier and located over 25miles but less than 50 miles from motherson site
C12: 5 | D12: New supplier and located over 50 miles from mothersonR site
D13: Score
B14: 2. Service/Good/Contract Delivery | C14: 1 | D14: Incumbent supplier with no performance issues, delivers on time and in full
C15: 2 | D15: Incumbent supplier - Previous delivery on time but not in full
C16: 3 | D16: Incumbent supplier - Previous delivery not on time or in full, being monitor for poor performance
C17: 4 | D17: New supplier - no delivery data spend <10K€
C18: 5 | D18: New supplier - no delivery data spend >10K€ or Incumbent not Delivered
D19: Score
B20: 3. Management | C20: 1 | D20: Incumbent supplier with no performance issues
C21: 2 | D21: Incumbent supplier with minor performance issues
C22: 3 | D22: Incumbent supplier with cautionery performance issues
C23: 4 | D23: New supplier - no performance data spend <10K€ or Incumbent supplier with major performance issues
C24: 5 | D24: New supplier - no performance data spend >10K€ or Incumbent supplier with major performance issues
D25: Score
B26: 4. Service | C26: 1 | D26: Support was instant at no additional cost or SLA under 24 hours
C27: 2 | D27: Support was instant with additional cost or SLA under 24 hours
C28: 3 | D28: Support was instant at no additional cost or SLA 48+ hours
C29: 4 | D29: Support was instant with additional cost or SLA 48+ hours
C30: 5 | D30: Support was +72 hours
D31: Score
B32: 5. Commerical | C32: 1 | D32: Best price and payment days provided after benchmarking
C33: 2 | D33: Best price provided after benchmarking
C34: 3 | D34: Competitive pricing but not lowest after benchmarking
C35: 4 | D35: Higher than competitors
C36: 5 | D36: Higher than competitors and also late to quote
D37: Score

Sheet Supp 2 risk
B2: RISK CATEGORY GUIDELINES | F2: Score card
F3: Between | H3: Category | I3: Comment
B4: These guidelines are to help indicate the relative risk of a supply situation. If the situation does not clearly fit into a guideline / example, use common sense. | F4: 1 | G4: 10 | H4: Preferred | I4: Supplier can be considered for nomination
F5: 11 | G5: 16 | H5: Cautionary | I5: Supplier score to be understood to identify what has driven score and to work with supplier to improve before nomination
C6: Score | D6: =SUM(C13+C19+C25+C31+C37) -> 0 | F6: 17 | G6: 20 | H6: Risk | I6: Supplier score to be understood to identify what has driven score and to work with supplier to improve for future potential business but cannot be nominated
B7: Risk / Category | C7: Rating (1-5) | D7: Guidelines | E7: Comment | F7: 21 | G7: 50 | H7: High risk | I7: Supplier cannot to be sourced
B8: 1. Supplier location | C8: 1 | D8: Incumbent supplier located within 25 miles to motherson site
C9: 2 | D9: Incumbent supplier and located over 25miles from motherson site
C10: 3 | D10: New supplier located within 25 miles to motherson site
C11: 4 | D11: New supplier and located over 25miles but less than 50 miles from motherson site
C12: 5 | D12: New supplier and located over 50 miles from mothersonR site
D13: Score
B14: 2. Service/Good/Contract Delivery | C14: 1 | D14: Incumbent supplier with no performance issues, delivers on time and in full
C15: 2 | D15: Incumbent supplier - Previous delivery on time but not in full
C16: 3 | D16: Incumbent supplier - Previous delivery not on time or in full, being monitor for poor performance
C17: 4 | D17: New supplier - no delivery data spend <10K€
C18: 5 | D18: New supplier - no delivery data spend >10K€ or Incumbent not Delivered
D19: Score
B20: 3. Management | C20: 1 | D20: Incumbent supplier with no performance issues
C21: 2 | D21: Incumbent supplier with minor performance issues
C22: 3 | D22: Incumbent supplier with cautionery performance issues
C23: 4 | D23: New supplier - no performance data spend <10K€ or Incumbent supplier with major performance issues
C24: 5 | D24: New supplier - no performance data spend >10K€ or Incumbent supplier with major performance issues
D25: Score
B26: 4. Service | C26: 1 | D26: Support was instant at no additional cost or SLA under 24 hours
C27: 2 | D27: Support was instant with additional cost or SLA under 24 hours
C28: 3 | D28: Support was instant at no additional cost or SLA 48+ hours
C29: 4 | D29: Support was instant with additional cost or SLA 48+ hours
C30: 5 | D30: Support was +72 hours
D31: Score
B32: 5. Commerical | C32: 1 | D32: Best price and payment days provided after benchmarking
C33: 2 | D33: Best price provided after benchmarking
C34: 3 | D34: Competitive pricing but not lowest after benchmarking
C35: 4 | D35: Higher than competitors
C36: 5 | D36: Higher than competitors and also late to quote
D37: Score

Sheet Supp 3 risk
B2: RISK CATEGORY GUIDELINES | F2: Score card
F3: Between | H3: Category | I3: Comment
B4: These guidelines are to help indicate the relative risk of a supply situation. If the situation does not clearly fit into a guideline / example, use common sense. | F4: 1 | G4: 10 | H4: Preferred | I4: Supplier can be considered for nomination
F5: 11 | G5: 16 | H5: Cautionary | I5: Supplier score to be understood to identify what has driven score and to work with supplier to improve before nomination
C6: Score | D6: =SUM(C13+C19+C25+C31+C37) -> 0 | F6: 17 | G6: 20 | H6: Risk | I6: Supplier score to be understood to identify what has driven score and to work with supplier to improve for future potential business but cannot be nominated
B7: Risk / Category | C7: Rating (1-5) | D7: Guidelines | E7: Comment | F7: 21 | G7: 50 | H7: High risk | I7: Supplier cannot to be sourced
B8: 1. Supplier location | C8: 1 | D8: Incumbent supplier located within 25 miles to motherson site
C9: 2 | D9: Incumbent supplier and located over 25miles from motherson site
C10: 3 | D10: New supplier located within 25 miles to motherson site
C11: 4 | D11: New supplier and located over 25miles but less than 50 miles from motherson site
C12: 5 | D12: New supplier and located over 50 miles from mothersonR site
D13: Score
B14: 2. Service/Good/Contract Delivery | C14: 1 | D14: Incumbent supplier with no performance issues, delivers on time and in full
C15: 2 | D15: Incumbent supplier - Previous delivery on time but not in full
C16: 3 | D16: Incumbent supplier - Previous delivery not on time or in full, being monitor for poor performance
C17: 4 | D17: New supplier - no delivery data spend <10K€
C18: 5 | D18: New supplier - no delivery data spend >10K€ or Incumbent not Delivered
D19: Score
B20: 3. Management | C20: 1 | D20: Incumbent supplier with no performance issues
C21: 2 | D21: Incumbent supplier with minor performance issues
C22: 3 | D22: Incumbent supplier with cautionery performance issues
C23: 4 | D23: New supplier - no performance data spend <10K€ or Incumbent supplier with major performance issues
C24: 5 | D24: New supplier - no performance data spend >10K€ or Incumbent supplier with major performance issues
D25: Score
B26: 4. Service | C26: 1 | D26: Support was instant at no additional cost or SLA under 24 hours
C27: 2 | D27: Support was instant with additional cost or SLA under 24 hours
C28: 3 | D28: Support was instant at no additional cost or SLA 48+ hours
C29: 4 | D29: Support was instant with additional cost or SLA 48+ hours
C30: 5 | D30: Support was +72 hours
D31: Score
B32: 5. Commerical | C32: 1 | D32: Best price and payment days provided after benchmarking
C33: 2 | D33: Best price provided after benchmarking
C34: 3 | D34: Competitive pricing but not lowest after benchmarking
C35: 4 | D35: Higher than competitors
C36: 5 | D36: Higher than competitors and also late to quote
D37: Score

Sheet Supp 4 risk
B2: RISK CATEGORY GUIDELINES | F2: Score card
F3: Between | H3: Category | I3: Comment
B4: These guidelines are to help indicate the relative risk of a supply situation. If the situation does not clearly fit into a guideline / example, use common sense. | F4: 1 | G4: 10 | H4: Preferred | I4: Supplier can be considered for nomination
F5: 11 | G5: 16 | H5: Cautionary | I5: Supplier score to be understood to identify what has driven score and to work with supplier to improve before nomination
C6: Score | D6: =SUM(C13+C19+C25+C31+C37) -> 0 | F6: 17 | G6: 20 | H6: Risk | I6: Supplier score to be understood to identify what has driven score and to work with supplier to improve for future potential business but cannot be nominated
B7: Risk / Category | C7: Rating (1-5) | D7: Guidelines | E7: Comment | F7: 21 | G7: 50 | H7: High risk | I7: Supplier cannot to be sourced
B8: 1. Supplier location | C8: 1 | D8: Incumbent supplier located within 25 miles to motherson site
C9: 2 | D9: Incumbent supplier and located over 25miles from motherson site
C10: 3 | D10: New supplier located within 25 miles to motherson site
C11: 4 | D11: New supplier and located over 25miles but less than 50 miles from motherson site
C12: 5 | D12: New supplier and located over 50 miles from mothersonR site
D13: Score
B14: 2. Service/Good/Contract Delivery | C14: 1 | D14: Incumbent supplier with no performance issues, delivers on time and in full
C15: 2 | D15: Incumbent supplier - Previous delivery on time but not in full
C16: 3 | D16: Incumbent supplier - Previous delivery not on time or in full, being monitor for poor performance
C17: 4 | D17: New supplier - no delivery data spend <10K€
C18: 5 | D18: New supplier - no delivery data spend >10K€ or Incumbent not Delivered
D19: Score
B20: 3. Management | C20: 1 | D20: Incumbent supplier with no performance issues
C21: 2 | D21: Incumbent supplier with minor performance issues
C22: 3 | D22: Incumbent supplier with cautionery performance issues
C23: 4 | D23: New supplier - no performance data spend <10K€ or Incumbent supplier with major performance issues
C24: 5 | D24: New supplier - no performance data spend >10K€ or Incumbent supplier with major performance issues
D25: Score
B26: 4. Service | C26: 1 | D26: Support was instant at no additional cost or SLA under 24 hours
C27: 2 | D27: Support was instant with additional cost or SLA under 24 hours
C28: 3 | D28: Support was instant at no additional cost or SLA 48+ hours
C29: 4 | D29: Support was instant with additional cost or SLA 48+ hours
C30: 5 | D30: Support was +72 hours
D31: Score
B32: 5. Commerical | C32: 1 | D32: Best price and payment days provided after benchmarking
C33: 2 | D33: Best price provided after benchmarking
C34: 3 | D34: Competitive pricing but not lowest after benchmarking
C35: 4 | D35: Higher than competitors
C36: 5 | D36: Higher than competitors and also late to quote
D37: Score

Sheet Supp 5 risk
B2: RISK CATEGORY GUIDELINES | F2: Score card
F3: Between | H3: Category | I3: Comment
B4: These guidelines are to help indicate the relative risk of a supply situation. If the situation does not clearly fit into a guideline / example, use common sense. | F4: 1 | G4: 10 | H4: Preferred | I4: Supplier can be considered for nomination
F5: 11 | G5: 16 | H5: Cautionary | I5: Supplier score to be understood to identify what has driven score and to work with supplier to improve before nomination
C6: Score | D6: =SUM(C13+C19+C25+C31+C37) -> 0 | F6: 17 | G6: 20 | H6: Risk | I6: Supplier score to be understood to identify what has driven score and to work with supplier to improve for future potential business but cannot be nominated
B7: Risk / Category | C7: Rating (1-5) | D7: Guidelines | E7: Comment | F7: 21 | G7: 50 | H7: High risk | I7: Supplier cannot to be sourced
B8: 1. Supplier location | C8: 1 | D8: Incumbent supplier located within 25 miles to motherson site
C9: 2 | D9: Incumbent supplier and located over 25miles from motherson site
C10: 3 | D10: New supplier located within 25 miles to motherson site
C11: 4 | D11: New supplier and located over 25miles but less than 50 miles from motherson site
C12: 5 | D12: New supplier and located over 50 miles from mothersonR site
D13: Score
B14: 2. Service/Good/Contract Delivery | C14: 1 | D14: Incumbent supplier with no performance issues, delivers on time and in full
C15: 2 | D15: Incumbent supplier - Previous delivery on time but not in full
C16: 3 | D16: Incumbent supplier - Previous delivery not on time or in full, being monitor for poor performance
C17: 4 | D17: New supplier - no delivery data spend <10K€
C18: 5 | D18: New supplier - no delivery data spend >10K€ or Incumbent not Delivered
D19: Score
B20: 3. Management | C20: 1 | D20: Incumbent supplier with no performance issues
C21: 2 | D21: Incumbent supplier with minor performance issues
C22: 3 | D22: Incumbent supplier with cautionery performance issues
C23: 4 | D23: New supplier - no performance data spend <10K€ or Incumbent supplier with major performance issues
C24: 5 | D24: New supplier - no performance data spend >10K€ or Incumbent supplier with major performance issues
D25: Score
B26: 4. Service | C26: 1 | D26: Support was instant at no additional cost or SLA under 24 hours
C27: 2 | D27: Support was instant with additional cost or SLA under 24 hours
C28: 3 | D28: Support was instant at no additional cost or SLA 48+ hours
C29: 4 | D29: Support was instant with additional cost or SLA 48+ hours
C30: 5 | D30: Support was +72 hours
D31: Score
B32: 5. Commerical | C32: 1 | D32: Best price and payment days provided after benchmarking
C33: 2 | D33: Best price provided after benchmarking
C34: 3 | D34: Competitive pricing but not lowest after benchmarking
C35: 4 | D35: Higher than competitors
C36: 5 | D36: Higher than competitors and also late to quote
D37: Score

Sheet Supp 6 risk
B2: RISK CATEGORY GUIDELINES | F2: Score card
F3: Between | H3: Category | I3: Comment
B4: These guidelines are to help indicate the relative risk of a supply situation. If the situation does not clearly fit into a guideline / example, use common sense. | F4: 1 | G4: 10 | H4: Preferred | I4: Supplier can be considered for nomination
F5: 11 | G5: 16 | H5: Cautionary | I5: Supplier score to be understood to identify what has driven score and to work with supplier to improve before nomination
C6: Score | D6: =SUM(C13+C19+C25+C31+C37) -> 0 | F6: 17 | G6: 20 | H6: Risk | I6: Supplier score to be understood to identify what has driven score and to work with supplier to improve for future potential business but cannot be nominated
B7: Risk / Category | C7: Rating (1-5) | D7: Guidelines | E7: Comment | F7: 21 | G7: 50 | H7: High risk | I7: Supplier cannot to be sourced
B8: 1. Supplier location | C8: 1 | D8: Incumbent supplier located within 25 miles to motherson site
C9: 2 | D9: Incumbent supplier and located over 25miles from motherson site
C10: 3 | D10: New supplier located within 25 miles to motherson site
C11: 4 | D11: New supplier and located over 25miles but less than 50 miles from motherson site
C12: 5 | D12: New supplier and located over 50 miles from mothersonR site
D13: Score
B14: 2. Service/Good/Contract Delivery | C14: 1 | D14: Incumbent supplier with no performance issues, delivers on time and in full
C15: 2 | D15: Incumbent supplier - Previous delivery on time but not in full
C16: 3 | D16: Incumbent supplier - Previous delivery not on time or in full, being monitor for poor performance
C17: 4 | D17: New supplier - no delivery data spend <10K€
C18: 5 | D18: New supplier - no delivery data spend >10K€ or Incumbent not Delivered
D19: Score
B20: 3. Management | C20: 1 | D20: Incumbent supplier with no performance issues
C21: 2 | D21: Incumbent supplier with minor performance issues
C22: 3 | D22: Incumbent supplier with cautionery performance issues
C23: 4 | D23: New supplier - no performance data spend <10K€ or Incumbent supplier with major performance issues
C24: 5 | D24: New supplier - no performance data spend >10K€ or Incumbent supplier with major performance issues
D25: Score
B26: 4. Service | C26: 1 | D26: Support was instant at no additional cost or SLA under 24 hours
C27: 2 | D27: Support was instant with additional cost or SLA under 24 hours
C28: 3 | D28: Support was instant at no additional cost or SLA 48+ hours
C29: 4 | D29: Support was instant with additional cost or SLA 48+ hours
C30: 5 | D30: Support was +72 hours
D31: Score
B32: 5. Commerical | C32: 1 | D32: Best price and payment days provided after benchmarking
C33: 2 | D33: Best price provided after benchmarking
C34: 3 | D34: Competitive pricing but not lowest after benchmarking
C35: 4 | D35: Higher than competitors
C36: 5 | D36: Higher than competitors and also late to quote
D37: Score

Sheet Supp 7 risk
B2: RISK CATEGORY GUIDELINES | F2: Score card
